2022-01-19 17:19:44,066 INFO    Thread-2  :8733 [wandb_setup.py:_flush():71] setting env: {'entity': 'amazonproject', 'project': 'Amazon-Reviews', 'root_dir': '/home/s133583/DTU/courses/ml_ops/project/MLOps_Amazon_review_project', 'sweep_id': 'ztyvw3il', 'run_id': 'e7b7n1gx', 'sweep_param_path': '/home/s133583/DTU/courses/ml_ops/project/MLOps_Amazon_review_project/wandb/sweep-ztyvw3il/config-e7b7n1gx.yaml'}
2022-01-19 17:19:44,066 INFO    Thread-2  :8733 [wandb_setup.py:_flush():71] setting login settings: {}
2022-01-19 17:19:44,066 INFO    Thread-2  :8733 [wandb_init.py:_log_setup():371] Logging user logs to /home/s133583/DTU/courses/ml_ops/project/MLOps_Amazon_review_project/wandb/run-20220119_171944-e7b7n1gx/logs/debug.log
2022-01-19 17:19:44,066 INFO    Thread-2  :8733 [wandb_init.py:_log_setup():372] Logging internal logs to /home/s133583/DTU/courses/ml_ops/project/MLOps_Amazon_review_project/wandb/run-20220119_171944-e7b7n1gx/logs/debug-internal.log
2022-01-19 17:19:44,067 INFO    Thread-2  :8733 [wandb_init.py:init():404] calling init triggers
2022-01-19 17:19:44,067 INFO    Thread-2  :8733 [wandb_init.py:init():409] wandb.init called with sweep_config: {'batch_size': 20, 'drop_out': 0.15, 'epochs': 1, 'lr': 0.01, 'num_workers': 4, 'optimizer': 'adam'}
config: {}
2022-01-19 17:19:44,067 INFO    Thread-2  :8733 [wandb_init.py:init():460] starting backend
2022-01-19 17:19:44,067 INFO    Thread-2  :8733 [backend.py:_multiprocessing_setup():99] multiprocessing start_methods=fork,spawn,forkserver, using: spawn
2022-01-19 17:19:44,085 INFO    Thread-2  :8733 [backend.py:ensure_launched():216] starting backend process...
2022-01-19 17:19:44,114 INFO    Thread-2  :8733 [backend.py:ensure_launched():221] started backend process with pid: 8748
2022-01-19 17:19:44,116 INFO    Thread-2  :8733 [wandb_init.py:init():469] backend started and connected
2022-01-19 17:19:44,122 INFO    Thread-2  :8733 [wandb_run.py:_config_callback():956] config_cb None None {'batch_size': 20, 'drop_out': 0.15, 'epochs': 1, 'lr': 0.01, 'num_workers': 4, 'optimizer': 'adam'}
2022-01-19 17:19:44,132 INFO    Thread-2  :8733 [wandb_init.py:init():533] updated telemetry
2022-01-19 17:19:44,175 INFO    Thread-2  :8733 [wandb_init.py:init():563] communicating current version
2022-01-19 17:19:48,715 INFO    Thread-2  :8733 [wandb_init.py:init():568] got version response 
2022-01-19 17:19:48,715 INFO    Thread-2  :8733 [wandb_init.py:init():578] communicating run to backend with 30 second timeout
2022-01-19 17:19:48,975 INFO    Thread-2  :8733 [wandb_init.py:init():606] starting run threads in backend
2022-01-19 17:19:51,204 INFO    Thread-2  :8733 [wandb_run.py:_console_start():1810] atexit reg
2022-01-19 17:19:51,205 INFO    Thread-2  :8733 [wandb_run.py:_redirect():1684] redirect: SettingsConsole.REDIRECT
2022-01-19 17:19:51,206 INFO    Thread-2  :8733 [wandb_run.py:_redirect():1689] Redirecting console.
2022-01-19 17:19:51,211 ERROR   Thread-2  :8733 [wandb_run.py:_redirect():1748] Failed to redirect.
Traceback (most recent call last):
  File "/home/s133583/anaconda3/envs/ml_ops_proj/lib/python3.9/site-packages/wandb/sdk/wandb_run.py", line 1741, in _redirect
    out_redir.install()
  File "/home/s133583/anaconda3/envs/ml_ops_proj/lib/python3.9/site-packages/wandb/sdk/lib/redirect.py", line 709, in install
    _WSCH.add_fd(self._pipe_read_fd)
  File "/home/s133583/anaconda3/envs/ml_ops_proj/lib/python3.9/site-packages/wandb/sdk/lib/redirect.py", line 659, in add_fd
    self._register()
  File "/home/s133583/anaconda3/envs/ml_ops_proj/lib/python3.9/site-packages/wandb/sdk/lib/redirect.py", line 644, in _register
    old_handler = signal.signal(signal.SIGWINCH, lambda *_: None)
  File "/home/s133583/anaconda3/envs/ml_ops_proj/lib/python3.9/signal.py", line 47, in signal
    handler = _signal.signal(_enum_to_int(signalnum), _enum_to_int(handler))
ValueError: signal only works in main thread of the main interpreter
2022-01-19 17:19:51,218 INFO    Thread-2  :8733 [wandb_init.py:init():633] run started, returning control to user process
2022-01-19 17:23:59,261 ERROR   Thread-1  :8733 [retry.py:__call__():126] Retry attempt failed:
Traceback (most recent call last):
  File "/home/s133583/anaconda3/envs/ml_ops_proj/lib/python3.9/site-packages/urllib3/connectionpool.py", line 699, in urlopen
    httplib_response = self._make_request(
  File "/home/s133583/anaconda3/envs/ml_ops_proj/lib/python3.9/site-packages/urllib3/connectionpool.py", line 382, in _make_request
    self._validate_conn(conn)
  File "/home/s133583/anaconda3/envs/ml_ops_proj/lib/python3.9/site-packages/urllib3/connectionpool.py", line 1010, in _validate_conn
    conn.connect()
  File "/home/s133583/anaconda3/envs/ml_ops_proj/lib/python3.9/site-packages/urllib3/connection.py", line 416, in connect
    self.sock = ssl_wrap_socket(
  File "/home/s133583/anaconda3/envs/ml_ops_proj/lib/python3.9/site-packages/urllib3/util/ssl_.py", line 449, in ssl_wrap_socket
    ssl_sock = _ssl_wrap_socket_impl(
  File "/home/s133583/anaconda3/envs/ml_ops_proj/lib/python3.9/site-packages/urllib3/util/ssl_.py", line 493, in _ssl_wrap_socket_impl
    return ssl_context.wrap_socket(sock, server_hostname=server_hostname)
  File "/home/s133583/anaconda3/envs/ml_ops_proj/lib/python3.9/ssl.py", line 500, in wrap_socket
    return self.sslsocket_class._create(
  File "/home/s133583/anaconda3/envs/ml_ops_proj/lib/python3.9/ssl.py", line 1040, in _create
    self.do_handshake()
  File "/home/s133583/anaconda3/envs/ml_ops_proj/lib/python3.9/ssl.py", line 1309, in do_handshake
    self._sslobj.do_handshake()
ssl.SSLEOFError: EOF occurred in violation of protocol (_ssl.c:1129)

During handling of the above exception, another exception occurred:

Traceback (most recent call last):
  File "/home/s133583/anaconda3/envs/ml_ops_proj/lib/python3.9/site-packages/requests/adapters.py", line 440, in send
    resp = conn.urlopen(
  File "/home/s133583/anaconda3/envs/ml_ops_proj/lib/python3.9/site-packages/urllib3/connectionpool.py", line 755, in urlopen
    retries = retries.increment(
  File "/home/s133583/anaconda3/envs/ml_ops_proj/lib/python3.9/site-packages/urllib3/util/retry.py", line 574, in increment
    raise MaxRetryError(_pool, url, error or ResponseError(cause))
urllib3.exceptions.MaxRetryError: HTTPSConnectionPool(host='api.wandb.ai', port=443): Max retries exceeded with url: /graphql (Caused by SSLError(SSLEOFError(8, 'EOF occurred in violation of protocol (_ssl.c:1129)')))

During handling of the above exception, another exception occurred:

Traceback (most recent call last):
  File "/home/s133583/anaconda3/envs/ml_ops_proj/lib/python3.9/site-packages/wandb/sdk/lib/retry.py", line 102, in __call__
    result = self._call_fn(*args, **kwargs)
  File "/home/s133583/anaconda3/envs/ml_ops_proj/lib/python3.9/site-packages/wandb/sdk/internal/internal_api.py", line 141, in execute
    return self.client.execute(*args, **kwargs)
  File "/home/s133583/anaconda3/envs/ml_ops_proj/lib/python3.9/site-packages/wandb/vendor/gql-0.2.0/gql/client.py", line 52, in execute
    result = self._get_result(document, *args, **kwargs)
  File "/home/s133583/anaconda3/envs/ml_ops_proj/lib/python3.9/site-packages/wandb/vendor/gql-0.2.0/gql/client.py", line 60, in _get_result
    return self.transport.execute(document, *args, **kwargs)
  File "/home/s133583/anaconda3/envs/ml_ops_proj/lib/python3.9/site-packages/wandb/vendor/gql-0.2.0/gql/transport/requests.py", line 38, in execute
    request = requests.post(self.url, **post_args)
  File "/home/s133583/anaconda3/envs/ml_ops_proj/lib/python3.9/site-packages/requests/api.py", line 117, in post
    return request('post', url, data=data, json=json, **kwargs)
  File "/home/s133583/anaconda3/envs/ml_ops_proj/lib/python3.9/site-packages/requests/api.py", line 61, in request
    return session.request(method=method, url=url, **kwargs)
  File "/home/s133583/anaconda3/envs/ml_ops_proj/lib/python3.9/site-packages/requests/sessions.py", line 529, in request
    resp = self.send(prep, **send_kwargs)
  File "/home/s133583/anaconda3/envs/ml_ops_proj/lib/python3.9/site-packages/requests/sessions.py", line 645, in send
    r = adapter.send(request, **kwargs)
  File "/home/s133583/anaconda3/envs/ml_ops_proj/lib/python3.9/site-packages/requests/adapters.py", line 517, in send
    raise SSLError(e, request=request)
requests.exceptions.SSLError: HTTPSConnectionPool(host='api.wandb.ai', port=443): Max retries exceeded with url: /graphql (Caused by SSLError(SSLEOFError(8, 'EOF occurred in violation of protocol (_ssl.c:1129)')))
