2022-01-19 18:01:06,615 INFO    Thread-7  :1298 [wandb_setup.py:_flush():71] setting env: {'entity': 'amazonproject', 'project': 'Amazon-Reviews', 'root_dir': '/home/s133583/DTU/courses/ml_ops/project/MLOps_Amazon_review_project', 'run_id': 'xo7mfoht', 'sweep_param_path': '/home/s133583/DTU/courses/ml_ops/project/MLOps_Amazon_review_project/wandb/sweep-kr7otbai/config-xo7mfoht.yaml', 'sweep_id': 'kr7otbai'}
2022-01-19 18:01:06,615 INFO    Thread-7  :1298 [wandb_setup.py:_flush():71] setting login settings: {}
2022-01-19 18:01:06,616 INFO    Thread-7  :1298 [wandb_init.py:_log_setup():371] Logging user logs to /home/s133583/DTU/courses/ml_ops/project/MLOps_Amazon_review_project/wandb/run-20220119_180106-xo7mfoht/logs/debug.log
2022-01-19 18:01:06,616 INFO    Thread-7  :1298 [wandb_init.py:_log_setup():372] Logging internal logs to /home/s133583/DTU/courses/ml_ops/project/MLOps_Amazon_review_project/wandb/run-20220119_180106-xo7mfoht/logs/debug-internal.log
2022-01-19 18:01:06,616 INFO    Thread-7  :1298 [wandb_init.py:init():404] calling init triggers
2022-01-19 18:01:06,616 INFO    Thread-7  :1298 [wandb_init.py:init():409] wandb.init called with sweep_config: {'batch_size': 20, 'drop_out': 0.15, 'epochs': 3, 'lr': 0.01, 'optimizer': 'sgd'}
config: {}
2022-01-19 18:01:06,616 INFO    Thread-7  :1298 [wandb_init.py:init():460] starting backend
2022-01-19 18:01:06,616 INFO    Thread-7  :1298 [backend.py:_multiprocessing_setup():99] multiprocessing start_methods=fork,spawn,forkserver, using: spawn
2022-01-19 18:01:06,626 INFO    Thread-7  :1298 [backend.py:ensure_launched():216] starting backend process...
2022-01-19 18:01:06,639 INFO    Thread-7  :1298 [backend.py:ensure_launched():221] started backend process with pid: 1350
2022-01-19 18:01:06,642 INFO    Thread-7  :1298 [wandb_init.py:init():469] backend started and connected
2022-01-19 18:01:06,646 INFO    Thread-7  :1298 [wandb_run.py:_config_callback():956] config_cb None None {'batch_size': 20, 'drop_out': 0.15, 'epochs': 3, 'lr': 0.01, 'optimizer': 'sgd'}
2022-01-19 18:01:06,651 INFO    Thread-7  :1298 [wandb_init.py:init():533] updated telemetry
2022-01-19 18:01:06,692 INFO    Thread-7  :1298 [wandb_init.py:init():563] communicating current version
2022-01-19 18:01:08,534 INFO    Thread-7  :1298 [wandb_init.py:init():568] got version response 
2022-01-19 18:01:08,534 INFO    Thread-7  :1298 [wandb_init.py:init():578] communicating run to backend with 30 second timeout
2022-01-19 18:01:08,788 INFO    Thread-7  :1298 [wandb_init.py:init():606] starting run threads in backend
2022-01-19 18:01:09,980 INFO    Thread-7  :1298 [wandb_run.py:_console_start():1810] atexit reg
2022-01-19 18:01:09,981 INFO    Thread-7  :1298 [wandb_run.py:_redirect():1684] redirect: SettingsConsole.REDIRECT
2022-01-19 18:01:09,981 INFO    Thread-7  :1298 [wandb_run.py:_redirect():1689] Redirecting console.
2022-01-19 18:01:09,982 ERROR   Thread-7  :1298 [wandb_run.py:_redirect():1748] Failed to redirect.
Traceback (most recent call last):
  File "/home/s133583/anaconda3/envs/ml_ops_proj/lib/python3.9/site-packages/wandb/sdk/wandb_run.py", line 1741, in _redirect
    out_redir.install()
  File "/home/s133583/anaconda3/envs/ml_ops_proj/lib/python3.9/site-packages/wandb/sdk/lib/redirect.py", line 709, in install
    _WSCH.add_fd(self._pipe_read_fd)
  File "/home/s133583/anaconda3/envs/ml_ops_proj/lib/python3.9/site-packages/wandb/sdk/lib/redirect.py", line 659, in add_fd
    self._register()
  File "/home/s133583/anaconda3/envs/ml_ops_proj/lib/python3.9/site-packages/wandb/sdk/lib/redirect.py", line 644, in _register
    old_handler = signal.signal(signal.SIGWINCH, lambda *_: None)
  File "/home/s133583/anaconda3/envs/ml_ops_proj/lib/python3.9/signal.py", line 47, in signal
    handler = _signal.signal(_enum_to_int(signalnum), _enum_to_int(handler))
ValueError: signal only works in main thread of the main interpreter
2022-01-19 18:01:09,987 INFO    Thread-7  :1298 [wandb_init.py:init():633] run started, returning control to user process
2022-01-19 18:01:28,333 INFO    Thread-7  :1298 [wandb_run.py:finish():1457] finishing run amazonproject/Amazon-Reviews/xo7mfoht
2022-01-19 18:01:28,333 INFO    Thread-7  :1298 [wandb_run.py:_atexit_cleanup():1780] got exitcode: 1
2022-01-19 18:01:28,335 INFO    Thread-7  :1298 [wandb_run.py:_restore():1752] restore
2022-01-19 18:01:31,258 ERROR   Thread-7  :1298 [wandb_run.py:_atexit_cleanup():1798] Problem finishing run
Traceback (most recent call last):
  File "/home/s133583/DTU/courses/ml_ops/project/MLOps_Amazon_review_project/src/models/train_model.py", line 143, in train
    wandb.log(
  File "/home/s133583/anaconda3/envs/ml_ops_proj/lib/python3.9/site-packages/wandb/sdk/wandb_run.py", line 1339, in log
    self.history._row_add(data)
  File "/home/s133583/anaconda3/envs/ml_ops_proj/lib/python3.9/site-packages/wandb/sdk/wandb_history.py", line 44, in _row_add
    self._flush()
  File "/home/s133583/anaconda3/envs/ml_ops_proj/lib/python3.9/site-packages/wandb/sdk/wandb_history.py", line 59, in _flush
    self._callback(row=self._data, step=self._step)
  File "/home/s133583/anaconda3/envs/ml_ops_proj/lib/python3.9/site-packages/wandb/sdk/wandb_run.py", line 1017, in _history_callback
    self._backend.interface.publish_history(
  File "/home/s133583/anaconda3/envs/ml_ops_proj/lib/python3.9/site-packages/wandb/sdk/interface/interface.py", line 496, in publish_history
    data = data_types.history_dict_to_json(run, data, step=step)
  File "/home/s133583/anaconda3/envs/ml_ops_proj/lib/python3.9/site-packages/wandb/sdk/data_types.py", line 2597, in history_dict_to_json
    payload[key] = val_to_json(run, key, val, namespace=step)
  File "/home/s133583/anaconda3/envs/ml_ops_proj/lib/python3.9/site-packages/wandb/sdk/data_types.py", line 2679, in val_to_json
    return val.to_json(run)
  File "/home/s133583/anaconda3/envs/ml_ops_proj/lib/python3.9/site-packages/wandb/data_types.py", line 544, in to_json
    json_dict = super(Table, self).to_json(run_or_artifact)
  File "/home/s133583/anaconda3/envs/ml_ops_proj/lib/python3.9/site-packages/wandb/sdk/data_types.py", line 562, in to_json
    assert (
AssertionError: We don't support referring to media files across runs.

During handling of the above exception, another exception occurred:

Traceback (most recent call last):
  File "/home/s133583/anaconda3/envs/ml_ops_proj/lib/python3.9/site-packages/wandb/sdk/wandb_run.py", line 1788, in _atexit_cleanup
    self._on_finish()
  File "/home/s133583/anaconda3/envs/ml_ops_proj/lib/python3.9/site-packages/wandb/sdk/wandb_run.py", line 1934, in _on_finish
    self.history._flush()
  File "/home/s133583/anaconda3/envs/ml_ops_proj/lib/python3.9/site-packages/wandb/sdk/wandb_history.py", line 59, in _flush
    self._callback(row=self._data, step=self._step)
  File "/home/s133583/anaconda3/envs/ml_ops_proj/lib/python3.9/site-packages/wandb/sdk/wandb_run.py", line 1017, in _history_callback
    self._backend.interface.publish_history(
  File "/home/s133583/anaconda3/envs/ml_ops_proj/lib/python3.9/site-packages/wandb/sdk/interface/interface.py", line 496, in publish_history
    data = data_types.history_dict_to_json(run, data, step=step)
  File "/home/s133583/anaconda3/envs/ml_ops_proj/lib/python3.9/site-packages/wandb/sdk/data_types.py", line 2597, in history_dict_to_json
    payload[key] = val_to_json(run, key, val, namespace=step)
  File "/home/s133583/anaconda3/envs/ml_ops_proj/lib/python3.9/site-packages/wandb/sdk/data_types.py", line 2679, in val_to_json
    return val.to_json(run)
  File "/home/s133583/anaconda3/envs/ml_ops_proj/lib/python3.9/site-packages/wandb/data_types.py", line 544, in to_json
    json_dict = super(Table, self).to_json(run_or_artifact)
  File "/home/s133583/anaconda3/envs/ml_ops_proj/lib/python3.9/site-packages/wandb/sdk/data_types.py", line 562, in to_json
    assert (
AssertionError: We don't support referring to media files across runs.
